Workbook
Name UPDATE: 'Raw Data'!$E$1

Sheet Financials>
B2: 3-Statement Model & Forecast - Mahindra & Mahindra LTD.
B5: 1 | C5: Summary Dashboard
B6: 2 | C6: Assumptions
B7: 3 | C7: Income Statement
B8: 4 | C8: Balance Sheet
B9: 5 | C9: Cash flow Statement
B10: 6 | C10: Sales Trend Analysis
B11: 7 | C11: Company Data
K13: BY - Mohd Anas

Sheet  Summary Dashboard
B1: Summary Dashboard - Mahindra & Mahindra LTD.
B4: Company Overview KPI's | D4: ='Income Statement '!I4 -> 2028
B6: Sales | D6: ='Income Statement '!I6 -> 203358.25
B7: Sales CAGR 2025-2028 | D7: =('Income Statement '!I6/'Income Statement '!F6)^(1/3)-1 -> 0.085
B8: EBITDA | D8: ='Income Statement '!I16 -> 42705.232
B9: Net Profit | D9: ='Income Statement '!I34 -> 20546.727
B10: Cash Balance | D10: ='Balance Sheet'!I23 -> 25337.712
B12: Growth & Profitability | D12: =D4 -> 2028
B14: Gross margin | D14: ='Income Statement '!I12 -> 0.315
B15: EBIT Margin | D15: ='Income Statement '!I22 -> 0.172
B16: EBITDA Margin | D16: ='Income Statement '!I17 -> 0.21
B17: Net Profit Margin | D17: ='Income Statement '!I35 -> 0.10103709
B19: Balance Sheet Strength | D19: =D12 -> 2028
B21: Debt/Equity | D21: =SUM('Balance Sheet'!I10:I11)/'Balance Sheet'!I8 -> 1.0445698
B22: Working Capital | D22: ='Balance Sheet'!I21+'Balance Sheet'!I22-'Balance Sheet'!I12 -> -9751.028
B23: Working Capital % of Sales | D23: =D22/D6 -> -0.04795
B25: Key Insights & Assumptions
A26: > | B26: Sales forecast assumes steady growth driven by continued strength in SUV and tractor segments, aligned with M&M’s rural demand exposure and domestic market leadership.
A27: > | B27: Operating margins are kept broadly stable, reflecting cost discipline and pricing power rather than aggressive efficiency expansion.
A28: > | B28: Operating margins are kept broadly stable, reflecting cost discipline and pricing power rather than aggressive efficiency expansion.
A29: > | B29: Capital expenditure assumed as a fixed % of sales to reflect ongoing investment in manufacturing capacity, EV transition, and product development.
A30: > | B30: D/E 1.04x Indicates balanced capital structure with moderate financial leverage supporting growth investments without excessive risk.

Sheet Assumptions
B1: Assumptions
A4: # | B4: Income Statement Assumptions | C4: 2026 | D4: 2027 | E4: 2028
B6: Sales
B7: Excel Forecast Implied Growth: | C7: ='Sales Trend Analysis'!E16 -> -0.045338984 | D7: ='Sales Trend Analysis'!E17 -> 0.064958377 | E7: ='Sales Trend Analysis'!E18 -> 0.060996165
B8: Historical Sales CAGR (10 Years) | C8: ='Sales Trend Analysis'!$E$24 -> 0.10258096 | D8: ='Sales Trend Analysis'!$E$24 -> 0.10258096 | E8: ='Sales Trend Analysis'!$E$24 -> 0.10258096
B9: Assumed Sales Growth Rate | C9: 0.085 | D9: 0.085 | E9: 0.085
B11: COGS % of Sales | C11: 0.685 | D11: 0.685 | E11: 0.685
B12: Selling & General Exp. %of Sales | C12: 0.105 | D12: 0.105 | E12: 0.105
B13: Depriciation % of Sales | C13: 0.038 | D13: 0.038 | E13: 0.038
B14: Interest Rate | C14: 0.07 | D14: 0.07 | E14: 0.07
B15: Tax Rate | C15: 0.25 | D15: 0.25 | E15: 0.25
A17: # | B17: Balance Sheet Assumptions | C17: 2026 | D17: 2027 | E17: 2028
B19: Dividend % of Profit for Equity Share Holder | C19: 0.2 | D19: 0.2 | E19: 0.2
B20: Trade Payables % of COGS | C20: 0.25 | D20: 0.25 | E20: 0.25
B21: Trade Receivables % of COGS | C21: 0.06 | D21: 0.06 | E21: 0.06
B22: Inventory % of COGS | C22: 0.12 | D22: 0.12 | E22: 0.12
B23: Debt Assumed Constant For Simplicity
B24: Capex
B25: Capex % of Sales | C25: 0.07 | D25: 0.07 | E25: 0.07
B26: Capex Amount | C26: ='Income Statement '!G6*Assumptions!C25 -> 12092.062 | D26: ='Income Statement '!H6*Assumptions!D25 -> 13119.887 | E26: ='Income Statement '!I6*Assumptions!E25 -> 14235.077
B27: CWIP | C27: ='Balance Sheet'!F17 -> 8298 | D27: 0 | E27: 0
B28: Net Capex for the Year | C28: =C26-C27 -> 3794.0618 | D28: =D26-D27 -> 13119.887 | E28: =E26-E27 -> 14235.077

Sheet Income Statement 
B1: Income Statement - Forecast
B3: Figures in INR Crores
A4: # | B4: Income Statement | C4: 2022 | D4: 2023 | E4: 2024 | F4: 2025 | G4: 2026 | H4: 2027 | I4: 2028
B6: Sales | C6: =IFERROR('Historical FS'!I5,0) -> 90170.57 | D6: =IFERROR('Historical FS'!J5,0) -> 121268.55 | E6: =IFERROR('Historical FS'!K5,0) -> 139078.27 | F6: =IFERROR('Historical FS'!L5,0) -> 159210.82 | G6: =F6*(1+Assumptions!C9) -> 172743.74 | H6: =G6*(1+Assumptions!D9) -> 187426.96 | I6: =H6*(1+Assumptions!E9) -> 203358.25
B7: Sales Growth | D7: =D6/C6-1 -> 0.34487949 | E7: =E6/D6-1 -> 0.14686182 | F7: =F6/E6-1 -> 0.14475698 | G7: =G6/F6-1 -> 0.085 | H7: =H6/G6-1 -> 0.085 | I7: =I6/H6-1 -> 0.085
B9: COGS | C9: =IFERROR('Historical FS'!I6,0) -> 63855.47 | D9: =IFERROR('Historical FS'!J6,0) -> 88334.41 | E9: =IFERROR('Historical FS'!K6,0) -> 98783.56 | F9: =IFERROR('Historical FS'!L6,0) -> 111863.52 | G9: =G6*G10 -> 118329.46 | H9: =H6*H10 -> 128387.47 | I9: =I6*I10 -> 139300.4
B10: COGS % of Sales | C10: =C9/C6 -> 0.7081631 | D10: =D9/D6 -> 0.72841978 | E10: =E9/E6 -> 0.71027314 | F10: =F9/F6 -> 0.70261255 | G10: =Assumptions!C11 -> 0.685 | H10: =Assumptions!D11 -> 0.685 | I10: =Assumptions!E11 -> 0.685
A11: # | B11: Gross Profit | C11: =C6-C9 -> 26315.1 | D11: =D6-D9 -> 32934.14 | E11: =E6-E9 -> 40294.71 | F11: =F6-F9 -> 47347.3 | G11: =G6-G9 -> 54414.278 | H11: =H6-H9 -> 59039.492 | I11: =I6-I9 -> 64057.848
B12: Gross Margin | C12: =C11/C6 -> 0.2918369 | D12: =D11/D6 -> 0.27158022 | E12: =E11/E6 -> 0.28972686 | F12: =F11/F6 -> 0.29738745 | G12: =G11/G6 -> 0.315 | H12: =H11/H6 -> 0.315 | I12: =I11/I6 -> 0.315
B14: Selling & General Exp. | C14: =IFERROR('Historical FS'!I9,0) -> 11632.25 | D14: =IFERROR('Historical FS'!J9,0) -> 12648.85 | E14: =IFERROR('Historical FS'!K9,0) -> 15402.78 | F14: =IFERROR('Historical FS'!L9,0) -> 16829.11 | G14: =G6*G15 -> 18138.093 | H14: =H6*H15 -> 19679.831 | I14: =I6*I15 -> 21352.616
B15: S&G Exp.% of Sales | C15: =C14/C6 -> 0.12900273 | D15: =D14/D6 -> 0.10430445 | E15: =E14/E6 -> 0.110749 | F15: =F14/F6 -> 0.10570331 | G15: =Assumptions!C12 -> 0.105 | H15: =Assumptions!D12 -> 0.105 | I15: =Assumptions!E12 -> 0.105
A16: # | B16: EBITDA | C16: =C11-C14 -> 14682.85 | D16: =D11-D14 -> 20285.29 | E16: =E11-E14 -> 24891.93 | F16: =F11-F14 -> 30518.19 | G16: =G11-G14 -> 36276.185 | H16: =H11-H14 -> 39359.661 | I16: =I11-I14 -> 42705.232
B17: EBITDA % of Sales | C17: =C16/C6 -> 0.16283417 | D17: =D16/D6 -> 0.16727577 | E17: =E16/E6 -> 0.17897785 | F17: =F16/F6 -> 0.19168415 | G17: =G16/G6 -> 0.21 | H17: =H16/H6 -> 0.21 | I17: =I16/I6 -> 0.21
B19: Depriciation | C19: =IFERROR('Historical FS'!I12,0) -> 3507.5 | D19: =IFERROR('Historical FS'!J12,0) -> 4356.81 | E19: =IFERROR('Historical FS'!K12,0) -> 4723.78 | F19: =IFERROR('Historical FS'!L12,0) -> 6073.65 | G19: =G6*G20 -> 6564.2621 | H19: =H6*H20 -> 7122.2244 | I19: =I6*I20 -> 7727.6135
B20: Depriciation % of Sales | C20: =IFERROR('Historical FS'!#REF!,0) -> 0 | D20: =IFERROR('Historical FS'!#REF!,0) -> 0 | E20: =IFERROR('Historical FS'!#REF!,0) -> 0 | F20: =IFERROR('Historical FS'!#REF!,0) -> 0 | G20: =Assumptions!C13 -> 0.038 | H20: =Assumptions!D13 -> 0.038 | I20: =Assumptions!E13 -> 0.038
B21: EBIT | C21: =C16-C19 -> 11175.35 | D21: =D16-D19 -> 15928.48 | E21: =E16-E19 -> 20168.15 | F21: =F16-F19 -> 24444.54 | G21: =G16-G19 -> 29711.923 | H21: =H16-H19 -> 32237.437 | I21: =I16-I19 -> 34977.619
B22: EBIT % of Sales | C22: =C21/C6 -> 0.12393567 | D22: =D21/D6 -> 0.13134881 | E22: =E21/E6 -> 0.14501295 | F22: =F21/F6 -> 0.15353567 | G22: =G21/G6 -> 0.172 | H22: =H21/H6 -> 0.172 | I22: =I21/I6 -> 0.172
B24: Other Non Operating income | C24: =IFERROR('Historical FS'!I15,0) -> 3204.47 | D24: =IFERROR('Historical FS'!J15,0) -> 3961.45 | E24: =IFERROR('Historical FS'!K15,0) -> 3297.85 | F24: =IFERROR('Historical FS'!L15,0) -> 3718.47 | G24: =AVERAGE($C$24:$F$24) -> 3545.56 | H24: =AVERAGE($C$24:$F$24) -> 3545.56 | I24: =AVERAGE($C$24:$F$24) -> 3545.56
B25: Profit Before Interest | C25: =C21+C24 -> 14379.82 | D25: =D21+D24 -> 19889.93 | E25: =E21+E24 -> 23466 | F25: =F21+F24 -> 28163.01 | G25: =G21+G24 -> 33257.483 | H25: =H21+H24 -> 35782.997 | I25: =I21+I24 -> 38523.179
B27: Interest | C27: =IFERROR('Historical FS'!I18,0) -> 5018.05 | D27: =IFERROR('Historical FS'!J18,0) -> 5829.7 | E27: =IFERROR('Historical FS'!K18,0) -> 7488.21 | F27: =IFERROR('Historical FS'!L18,0) -> 9083.39 | G27: =F27*(1+Assumptions!C14) -> 9719.2273 | H27: =G27*(1+Assumptions!D14) -> 10399.573 | I27: =H27*(1+Assumptions!E14) -> 11127.543
B28: Interest % of Sales | C28: =C27/C6 -> 0.055650641 | D28: =D27/D6 -> 0.048072645 | E28: =E27/E6 -> 0.053841696 | F28: =F27/F6 -> 0.057052592 | G28: =G27/G6 -> 0.056263847 | H28: =H27/H6 -> 0.055486006 | I28: =I27/I6 -> 0.054718918
B29: Profit Before Tax | C29: =C25-C27 -> 9361.77 | D29: =D25-D27 -> 14060.23 | E29: =E25-E27 -> 15977.79 | F29: =F25-F27 -> 19079.62 | G29: =G25-G27 -> 23538.256 | H29: =H25-H27 -> 25383.423 | I29: =I25-I27 -> 27395.635
B30: EBT % of Sales | C30: =C29/C6 -> 0.1038229 | D30: =D29/D6 -> 0.11594292 | E30: =E29/E6 -> 0.11488344 | F30: =F29/F6 -> 0.11983871 | G30: =G29/G6 -> 0.13626112 | H30: =H29/H6 -> 0.13543102 | I30: =I29/I6 -> 0.13471613
B32: Tax | C32: =IFERROR('Historical FS'!I21,0) -> 2108.76 | D32: =IFERROR('Historical FS'!J21,0) -> 2685.75 | E32: =IFERROR('Historical FS'!K21,0) -> 3707.97 | F32: =IFERROR('Historical FS'!L21,0) -> 5006.45 | G32: =G29*G33 -> 5884.564 | H32: =H29*H33 -> 6345.8559 | I32: =I29*I33 -> 6848.9089
B33: Effective Tax Rate | C33: =IFERROR('Historical FS'!I22,0) -> 0.22525228 | D33: =IFERROR('Historical FS'!J22,0) -> 0.1910175 | E33: =IFERROR('Historical FS'!K22,0) -> 0.23207027 | F33: =IFERROR('Historical FS'!L22,0) -> 0.26239778 | G33: =Assumptions!C15 -> 0.25 | H33: =Assumptions!D15 -> 0.25 | I33: =Assumptions!E15 -> 0.25
A34: # | B34: Net Profit | C34: =C29-C32 -> 7253.01 | D34: =D29-D32 -> 11374.48 | E34: =E29-E32 -> 12269.82 | F34: =F29-F32 -> 14073.17 | G34: =G29-G32 -> 17653.692 | H34: =H29-H32 -> 19037.568 | I34: =I29-I32 -> 20546.727
B35: Net Margins | C35: =C34/C6 -> 0.080436555 | D35: =D34/D6 -> 0.093795795 | E35: =E34/E6 -> 0.088222409 | F35: =F34/F6 -> 0.088393301 | G35: =G34/G6 -> 0.10219584 | H35: =H34/H6 -> 0.10157326 | I35: =I34/I6 -> 0.10103709
B37: Minority Share | C37: =IFERROR('Historical FS'!I25,0) -> -676 | D37: =IFERROR('Historical FS'!J25,0) -> -1093 | E37: =IFERROR('Historical FS'!K25,0) -> -1001 | F37: =IFERROR('Historical FS'!L25,0) -> -1144 | G37: =F37 -> -1144 | H37: =G37 -> -1144 | I37: =H37 -> -1144
B38: Profit for Equity Share Holder | C38: =SUM(C34,C37) -> 6577.01 | D38: =SUM(D34,D37) -> 10281.48 | E38: =SUM(E34,E37) -> 11268.82 | F38: =SUM(F34,F37) -> 12929.17 | G38: =SUM(G34,G37) -> 16509.692 | H38: =SUM(H34,H37) -> 17893.568 | I38: =SUM(I34,I37) -> 19402.727
B40: Dividend Paid % | C40: =IFERROR('Historical FS'!I34,0) -> 0.19530151 | D40: =IFERROR('Historical FS'!J34,0) -> 0.17601162 | E40: =IFERROR('Historical FS'!K34,0) -> 0.20872993 | F40: =IFERROR('Historical FS'!L34,0) -> 0.21843939 | G40: =Assumptions!C19 -> 0.2 | H40: =Assumptions!D19 -> 0.2 | I40: =Assumptions!E19 -> 0.2
B41: Dividend Amount | C41: =C38*C40 -> 1284.5 | D41: =D38*D40 -> 1809.66 | E41: =E38*E40 -> 2352.14 | F41: =F38*F40 -> 2824.24 | G41: =G38*G40 -> 3301.9384 | H41: =H38*H40 -> 3578.7135 | I41: =I38*I40 -> 3880.5453
B43: Retained Earning in % | C43: =IFERROR(IF('Income Statement '!C38>'Income Statement '!C41,1-'Income Statement '!C40,0),0) -> 0.80469849 | D43: =IFERROR(IF('Income Statement '!D38>'Income Statement '!D41,1-'Income Statement '!D40,0),0) -> 0.82398838 | E43: =IFERROR(IF('Income Statement '!E38>'Income Statement '!E41,1-'Income Statement '!E40,0),0) -> 0.79127007 | F43: =IFERROR(IF('Income Statement '!F38>'Income Statement '!F41,1-'Income Statement '!F40,0),0) -> 0.78156061 | G43: =IFERROR(IF('Income Statement '!G38>'Income Statement '!G41,1-'Income Statement '!G40,0),0) -> 0.8 | H43: =IFERROR(IF('Income Statement '!H38>'Income Statement '!H41,1-'Income Statement '!H40,0),0) -> 0.8 | I43: =IFERROR(IF('Income Statement '!I38>'Income Statement '!I41,1-'Income Statement '!I40,0),0) -> 0.8
A44: # | B44: Retained Amount | C44: =C38-C41 -> 5292.51 | D44: =D38-D41 -> 8471.82 | E44: =E38-E41 -> 8916.68 | F44: =F38-F41 -> 10104.93 | G44: =G38-G41 -> 13207.754 | H44: =H38-H41 -> 14314.854 | I44: =I38-I41 -> 15522.181

Sheet Balance Sheet
B1: Balance Sheet - Forecast
A4: # | B4: Balance Sheet | C4: ='Income Statement '!C4 -> 2022 | D4: ='Income Statement '!D4 -> 2023 | E4: ='Income Statement '!E4 -> 2024 | F4: ='Income Statement '!F4 -> 2025 | G4: ='Income Statement '!G4 -> 2026 | H4: ='Income Statement '!H4 -> 2027 | I4: ='Income Statement '!I4 -> 2028
B6: Equity Share Capital | C6: =IFERROR('Historical FS'!I40,0) -> 556 | D6: =IFERROR('Historical FS'!J40,0) -> 556 | E6: =IFERROR('Historical FS'!K40,0) -> 557 | F6: =IFERROR('Historical FS'!L40,0) -> 558 | G6: =F6 -> 558 | H6: =G6 -> 558 | I6: =H6 -> 558
B7: Reserves | C7: =IFERROR('Historical FS'!I41,0) -> 46566 | D7: =IFERROR('Historical FS'!J41,0) -> 55809 | E7: =IFERROR('Historical FS'!K41,0) -> 65631 | F7: =IFERROR('Historical FS'!L41,0) -> 76484 | G7: =F7+'Income Statement '!G34-'Income Statement '!G41 -> 90835.754 | H7: =G7+'Income Statement '!H34-'Income Statement '!H41 -> 106294.61 | I7: =H7+'Income Statement '!I34-'Income Statement '!I41 -> 122960.79
B8: Total Equity | C8: =C7+C6 -> 47122 | D8: =D7+D6 -> 56365 | E8: =E7+E6 -> 66188 | F8: =F7+F6 -> 77042 | G8: =G7+G6 -> 91393.754 | H8: =H7+H6 -> 106852.61 | I8: =I7+I6 -> 123518.79
B10: Long term Borrowings | C10: =IFERROR('Historical FS'!I43,0) -> 48625 | D10: =IFERROR('Historical FS'!J43,0) -> 55027 | E10: =IFERROR('Historical FS'!K43,0) -> 69741 | F10: =IFERROR('Historical FS'!L43,0) -> 83782 | G10: =F10 -> 83782 | H10: =G10 -> 83782 | I10: =H10 -> 83782
B11: Short term Borrowings | C11: =IFERROR(SUM('Historical FS'!I44:I47),0) -> 28980 | D11: =IFERROR(SUM('Historical FS'!J44:J47),0) -> 37220 | E11: =IFERROR(SUM('Historical FS'!K44:K47),0) -> 38906 | F11: =IFERROR(SUM('Historical FS'!L44:L47),0) -> 45242 | G11: =F11 -> 45242 | H11: =G11 -> 45242 | I11: =H11 -> 45242
B12: Trade Payables | C12: =IFERROR('Historical FS'!I50,0) -> 19037 | D12: =IFERROR('Historical FS'!J50,0) -> 23836 | E12: =IFERROR('Historical FS'!K50,0) -> 25666 | F12: =IFERROR('Historical FS'!L50,0) -> 30855 | G12: ='Income Statement '!G9*Assumptions!C20 -> 29582.365 | H12: ='Income Statement '!H9*Assumptions!D20 -> 32096.866 | I12: ='Income Statement '!I9*Assumptions!E20 -> 34825.1
B13: Other Liabilities | C13: =IFERROR(SUM('Historical FS'!I52,'Historical FS'!I49),0) -> 28624 | D13: =IFERROR(SUM('Historical FS'!J52,'Historical FS'!J49),0) -> 31835 | E13: =IFERROR(SUM('Historical FS'!K52,'Historical FS'!K49),0) -> 34219 | F13: =IFERROR(SUM('Historical FS'!L52,'Historical FS'!L49),0) -> 39094 | G13: =F13 -> 39094 | H13: =G13 -> 39094 | I13: =H13 -> 39094
B14: Total Laibilities | C14: =SUM(C13,C12,C11,C10,C8) -> 172388 | D14: =SUM(D13,D12,D11,D10,D8) -> 204283 | E14: =SUM(E13,E12,E11,E10,E8) -> 234720 | F14: =SUM(F13,F12,F11,F10,F8) -> 276015 | G14: =SUM(G13,G12,G11,G10,G8) -> 289094.12 | H14: =SUM(H13,H12,H11,H10,H8) -> 307067.47 | I14: =SUM(I13,I12,I11,I10,I8) -> 326461.89
B16: Fixed Asset Net Block | C16: =IFERROR('Historical FS'!I65,0) -> 26018 | D16: =IFERROR('Historical FS'!J65,0) -> 27140 | E16: =IFERROR('Historical FS'!K65,0) -> 28129 | F16: =IFERROR('Historical FS'!L65,0) -> 34637 | G16: =(SUM(F16+F17+Assumptions!C28)-'Income Statement '!G19) -> 40164.8 | H16: =(SUM(G16+G17+Assumptions!D28)-'Income Statement '!H19) -> 46162.462 | I16: =(SUM(H16+H17+Assumptions!E28)-'Income Statement '!I19) -> 52669.926
B17: CWIP | C17: =IFERROR('Historical FS'!I67,0) -> 6703 | D17: =IFERROR('Historical FS'!J67,0) -> 3969 | E17: =IFERROR('Historical FS'!K67,0) -> 8039 | F17: =IFERROR('Historical FS'!L67,0) -> 8298 | G17: 0 | H17: 0 | I17: 0
B18: Investments | C18: =IFERROR('Historical FS'!I68,0) -> 30060 | D18: =IFERROR('Historical FS'!J68,0) -> 35272 | E18: =IFERROR('Historical FS'!K68,0) -> 35208 | F18: =IFERROR('Historical FS'!L68,0) -> 41309 | G18: =F18 -> 41309 | H18: =G18 -> 41309 | I18: =H18 -> 41309
B19: Total Non Current Asset | C19: =SUM(C16:C18) -> 62781 | D19: =SUM(D16:D18) -> 66381 | E19: =SUM(E16:E18) -> 71376 | F19: =SUM(F16:F18) -> 84244 | G19: =SUM(G16:G18) -> 81473.8 | H19: =SUM(H16:H18) -> 87471.462 | I19: =SUM(I16:I18) -> 93978.926
B21: Trade Receivables | C21: =IFERROR('Historical FS'!I71,0) -> 6374 | D21: =IFERROR('Historical FS'!J71,0) -> 7028 | E21: =IFERROR('Historical FS'!K71,0) -> 7459 | F21: =IFERROR('Historical FS'!L71,0) -> 8280 | G21: ='Income Statement '!G9*Assumptions!C21 -> 7099.7677 | H21: ='Income Statement '!H9*Assumptions!D21 -> 7703.248 | I21: ='Income Statement '!I9*Assumptions!E21 -> 8358.024
B22: Inventory | C22: =IFERROR('Historical FS'!I70,0) -> 11596 | D22: =IFERROR('Historical FS'!J70,0) -> 16855 | E22: =IFERROR('Historical FS'!K70,0) -> 18590 | F22: =IFERROR('Historical FS'!L70,0) -> 20331 | G22: ='Income Statement '!G9*Assumptions!C22 -> 14199.535 | H22: ='Income Statement '!H9*Assumptions!D22 -> 15406.496 | I22: ='Income Statement '!I9*Assumptions!E22 -> 16716.048
B23: Cash & Bank | C23: =IFERROR('Historical FS'!I72,0) -> 11118 | D23: =IFERROR('Historical FS'!J72,0) -> 11273 | E23: =IFERROR('Historical FS'!K72,0) -> 12013 | F23: =IFERROR('Historical FS'!L72,0) -> 20615 | G23: =F23+'Cash Flow Statement'!C24 -> 31659.691 | H23: =G23+'Cash Flow Statement'!D24 -> 28678.73 | I23: =H23+'Cash Flow Statement'!E24 -> 25337.712
B24: Other asset items | C24: =IFERROR(SUM('Historical FS'!I73,'Historical FS'!I74),0) -> 80519 | D24: =IFERROR(SUM('Historical FS'!J73,'Historical FS'!J74),0) -> 102746 | E24: =IFERROR(SUM('Historical FS'!K73,'Historical FS'!K74),0) -> 125282 | F24: =IFERROR(SUM('Historical FS'!L73,'Historical FS'!L74),0) -> 142545 | G24: =F24*(1+'Income Statement '!G7) -> 154661.32 | H24: =G24*(1+'Income Statement '!H7) -> 167807.54 | I24: =H24*(1+'Income Statement '!I7) -> 182071.18
B25: Total Current Assets | C25: =IFERROR(SUM(C21:C24),0) -> 109607 | D25: =IFERROR(SUM(D21:D24),0) -> 137902 | E25: =IFERROR(SUM(E21:E24),0) -> 163344 | F25: =IFERROR(SUM(F21:F24),0) -> 191771 | G25: =IFERROR(SUM(G21:G24),0) -> 207620.32 | H25: =IFERROR(SUM(H21:H24),0) -> 219596.01 | I25: =IFERROR(SUM(I21:I24),0) -> 232482.96
B26: Total Assets | C26: =IFERROR(SUM(C25,C19),0) -> 172388 | D26: =IFERROR(SUM(D25,D19),0) -> 204283 | E26: =IFERROR(SUM(E25,E19),0) -> 234720 | F26: =IFERROR(SUM(F25,F19),0) -> 276015 | G26: =IFERROR(SUM(G25,G19),0) -> 289094.12 | H26: =IFERROR(SUM(H25,H19),0) -> 307067.47 | I26: =IFERROR(SUM(I25,I19),0) -> 326461.89
A28: # | B28: Check | C28: =C26=C14 -> TRUE | D28: =D26=D14 -> TRUE | E28: =E26=E14 -> TRUE | F28: =F26=F14 -> TRUE | G28: =G26=G14 -> TRUE | H28: =H26=H14 -> TRUE | I28: =I26=I14 -> TRUE

Sheet Cash Flow Statement
B1: Cash Flow Statement - Forecast
A4: # | B4: Cash Flow Statements | C4: 2026 | D4: 2027 | E4: 2028
B6: Operating Activities
B7: Net profit | C7: ='Income Statement '!G34 -> 17653.692 | D7: ='Income Statement '!H34 -> 19037.568 | E7: ='Income Statement '!I34 -> 20546.727
B8: Depriciation | C8: ='Income Statement '!G19 -> 6564.2621 | D8: ='Income Statement '!H19 -> 7122.2244 | E8: ='Income Statement '!I19 -> 7727.6135
B9: Change in Trade Receivables | C9: =-('Balance Sheet'!G21-'Balance Sheet'!F21) -> 1180.2323 | D9: =-('Balance Sheet'!H21-'Balance Sheet'!G21) -> -603.48025 | E9: =-('Balance Sheet'!I21-'Balance Sheet'!H21) -> -654.77608
B10: Change in Trade Payables | C10: =('Balance Sheet'!G12-'Balance Sheet'!F12) -> -1272.6346 | D10: =('Balance Sheet'!H12-'Balance Sheet'!G12) -> 2514.5011 | E10: =('Balance Sheet'!I12-'Balance Sheet'!H12) -> 2728.2337
B11: Change in Inventory | C11: =-('Balance Sheet'!G22-'Balance Sheet'!F22) -> 6131.4646 | D11: =-('Balance Sheet'!H22-'Balance Sheet'!G22) -> -1206.9605 | E11: =-('Balance Sheet'!I22-'Balance Sheet'!H22) -> -1309.5522
B12: Cash from Operating Activities | C12: =SUM(C7:C11) -> 30257.016 | D12: =SUM(D7:D11) -> 26863.852 | E12: =SUM(E7:E11) -> 29038.245
B14: Investing Activities
B15: Capex | C15: =-Assumptions!C28 -> -3794.0618 | D15: =-Assumptions!D28 -> -13119.887 | E15: =-Assumptions!E28 -> -14235.077
B16: Change in Other Asset | C16: =-('Balance Sheet'!G24-'Balance Sheet'!F24) -> -12116.325 | D16: =-('Balance Sheet'!H24-'Balance Sheet'!G24) -> -13146.213 | E16: =-('Balance Sheet'!I24-'Balance Sheet'!H24) -> -14263.641
B17: Cash from Investing Activities | C17: =SUM(C15:C16) -> -15910.387 | D17: =SUM(D15:D16) -> -26266.1 | E17: =SUM(E15:E16) -> -28498.718
B19: Financing Activities
B20: Change in Debt | C20: =-(SUM('Balance Sheet'!G10:G11)-SUM('Balance Sheet'!F10:F11)) -> 0 | D20: =-(SUM('Balance Sheet'!H10:H11)-SUM('Balance Sheet'!G10:G11)) -> 0 | E20: =-(SUM('Balance Sheet'!I10:I11)-SUM('Balance Sheet'!H10:H11)) -> 0
B21: Dividends paid | C21: =-'Income Statement '!G41 -> -3301.9384 | D21: =-'Income Statement '!H41 -> -3578.7135 | E21: =-'Income Statement '!I41 -> -3880.5453
B22: Cash from FinancingActivities | C22: =SUM(C20:C21) -> -3301.9384 | D22: =SUM(D20:D21) -> -3578.7135 | E22: =SUM(E20:E21) -> -3880.5453
A24: # | B24: Net Cash Flow | C24: =SUM(C12,C17,C22) -> 11044.691 | D24: =SUM(D12,D17,D22) -> -2980.9609 | E24: =SUM(E12,E17,E22) -> -3341.018

Sheet Sales Trend Analysis
B1: ="Sales Forecasting - "&'Raw Data'!B1 -> Sales Forecasting - MAHINDRA & MAHINDRA LTD
A4: # | B4: Weight of year | C4: Year | D4: Sales | E4: Sales Growth
B6: 1 | C6: 2016 | D6: 57589 | E6: =-E6 -> 0
B7: =B6+1 -> 2 | C7: 2017 | D7: 68085 | E7: =D7/D6-1 -> 0.18225703
B8: =B7+1 -> 3 | C8: 2018 | D8: 79809.4 | E8: =D8/D7-1 -> 0.17220239
B9: =B8+1 -> 4 | C9: 2019 | D9: 86068.5 | E9: =D9/D8-1 -> 0.078425599
B10: =B9+1 -> 5 | C10: 2020 | D10: 75660 | E10: =D10/D9-1 -> -0.12093275
B11: =B10+1 -> 6 | C11: 2021 | D11: 70372 | E11: =D11/D10-1 -> -0.06989162
B12: =B11+1 -> 7 | C12: 2022 | D12: 88329.8 | E12: =D12/D11-1 -> 0.25518388
B13: =B12+1 -> 8 | C13: 2023 | D13: 117571.3 | E13: =D13/D12-1 -> 0.33104909
B14: =B13+1 -> 9 | C14: 2024 | D14: 141858.2 | E14: =D14/D13-1 -> 0.20657167
B15: =B14+1 -> 10 | C15: 2025 | D15: 152913 | E15: =D15/D14-1 -> 0.077928523
B16: =B15+1 -> 11 | C16: 2026 | D16: =FORECAST(B16,$D$6:$D$15,$B$6:$B$15) -> 145980.08 | E16: =D16/D15-1 -> -0.045338984
B17: =B16+1 -> 12 | C17: 2027 | D17: =FORECAST(B17,$D$6:$D$15,$B$6:$B$15) -> 155462.71 | E17: =D17/D16-1 -> 0.064958377
B18: =B17+1 -> 13 | C18: 2028 | D18: =FORECAST(B18,$D$6:$D$15,$B$6:$B$15) -> 164945.34 | E18: =D18/D17-1 -> 0.060996165
A20: # | B20: Sales Growth CAGR (10 years)
B22: 1st year sales | E22: =D6 -> 57589
B23: 10th year sales | E23: =D15 -> 152913
B24: 10 years Sales CAGR | E24: =(E23/E22)^(1/10)-1 -> 0.10258096

Sheet Historical FS
B2: Hitorical Financial Statement - MAHINDRA & MAHINDRA LTD.
B3: Figures in INR
A4: # | B4: Income Statement | C4: 2016 | D4: =C4+1 -> 2017 | E4: =D4+1 -> 2018 | F4: =E4+1 -> 2019 | G4: =F4+1 -> 2020 | H4: =G4+1 -> 2021 | I4: =H4+1 -> 2022 | J4: =I4+1 -> 2023 | K4: =J4+1 -> 2024 | L4: =K4+1 -> 2025
B5: Sales | C5: 75841.42 | D5: 83773.05 | E5: 92093.95 | F5: 104720.68 | G5: 75381.93 | H5: 74277.78 | I5: 90170.57 | J5: 121268.55 | K5: 139078.27 | L5: 159210.82
B6: COGS | C6: 56073.91 | D6: 63464.36 | E6: 67869.4 | F6: 76462.9 | G6: 50445.45 | H6: 49173.01 | I6: 63855.47 | J6: 88334.41 | K6: 98783.56 | L6: 111863.52
B7: Gross Profit | C7: 19767.51 | D7: 20308.69 | E7: 24224.55 | F7: 28257.78 | G7: 24936.48 | H7: 25104.77 | I7: 26315.1 | J7: 32934.14 | K7: 40294.71 | L7: 47347.3
B9: Selling & General Exp. | C9: 9685.07 | D9: 9573.86 | E9: 10998.45 | F9: 13051.27 | G9: 14778.73 | H9: 13617.75 | I9: 11632.25 | J9: 12648.85 | K9: 15402.78 | L9: 16829.11
B10: EBITDA | C10: 10082.44 | D10: 10734.83 | E10: 13226.1 | F10: 15206.51 | G10: 10157.75 | H10: 11487.02 | I10: 14682.85 | J10: 20285.29 | K10: 24891.93 | L10: 30518.19
B12: Depriciation | C12: 2441.65 | D12: 2812.72 | E12: 3279.9 | F12: 3990.77 | G12: 3366.68 | H12: 3378.11 | I12: 3507.5 | J12: 4356.81 | K12: 4723.78 | L12: 6073.65
B13: EBIT | C13: 7640.79 | D13: 7922.11 | E13: 9946.2 | F13: 11215.74 | G13: 6791.07 | H13: 8108.91 | I13: 11175.35 | J13: 15928.48 | K13: 20168.15 | L13: 24444.54
B15: Other Non Operating income | C15: 1398.83 | D15: 2076.61 | E15: 4366.41 | F15: 2676.45 | G15: 884.69 | H15: 1151.51 | I15: 3204.47 | J15: 3961.45 | K15: 3297.85 | L15: 3718.47
B16: Profit Before Interest | C16: 9039.62 | D16: 9998.72 | E16: 14312.61 | F16: 13892.19 | G16: 7675.76 | H16: 9260.42 | I16: 14379.82 | J16: 19889.93 | K16: 23466 | L16: 28163.01
B18: Interest | C18: 3367.59 | D18: 3648.46 | E18: 3987.09 | F18: 5021.35 | G18: 6021.15 | H18: 6102.22 | I18: 5018.05 | J18: 5829.7 | K18: 7488.21 | L18: 9083.39
B19: Profit Before Tax | C19: 5672.03 | D19: 6350.26 | E19: 10325.52 | F19: 8870.84 | G19: 1654.61 | H19: 3158.2 | I19: 9361.77 | J19: 14060.23 | K19: 15977.79 | L19: 19079.62
B21: Tax | C21: 2117.53 | D21: 2299.73 | E21: 2367.73 | F21: 2853.99 | G21: 1975.61 | H21: 1645.81 | I21: 2108.76 | J21: 2685.75 | K21: 3707.97 | L21: 5006.45
... B30: Earning per share (EPS) | C30: 25.34616 | D30: 29.77403 | E30: 60.414977 | F30: 42.759411 | G30: 1.0215573 | H30: 14.578427 | I30: 52.903877 | J30: 82.681785 | K30: 90.621793 | L30: 103.97402
B31: EPS Growth Rate % | D31: 0.17469589 | E31: 1.0291166 | F31: -0.29223823 | G31: -0.97610918 | H31: 13.270787 | I31: 2.6289154 | J31: 0.56286816 | K31: 0.096030922 | L31: 0.14734018
B33: Dividend per share | C33: 5.2242795 | D33: 6.5 | E33: 6.5532497 | F33: 7.4383044 | G33: 2.0954794 | H33: 7.8145914 | I33: 10.332207 | J33: 14.552955 | K33: 18.91548 | L33: 22.712023
B34: Dividend Ratio | C34: 0.2061172 | D34: 0.21831106 | E34: 0.10847061 | F34: 0.17395713 | G34: 2.0512598 | H34: 0.53603805 | I34: 0.19530151 | J34: 0.17601162 | K34: 0.20872993 | L34: 0.21843939
B36: Retained Earning in % | C36: 0.7938828 | D36: 0.78168894 | E36: 0.89152939 | F36: 0.82604287 | G36: 0 | H36: 0.46396195 | I36: 0.80469849 | J36: 0.82398838 | K36: 0.79127007 | L36: 0.78156061
A39: # | B39: Balance Sheet | C39: =C4 -> 2016 | D39: =D4 -> 2017 | E39: =E4 -> 2018 | F39: =F4 -> 2019 | G39: =G4 -> 2020 | H39: =H4 -> 2021 | I39: =I4 -> 2022 | J39: =J4 -> 2023 | ... L39: =L4 -> 2025
B40: Equity Capital | C40: 270 | D40: 311 | E40: 543 | F40: 544 | G40: 554 | H40: 555 | I40: 556 | J40: 556 | K40: 557 | L40: 558
B41: Reserves | C41: 26222 | D41: 29467 | E41: 36232 | F41: 39439 | G41: 39415 | H41: 41027 | I41: 46566 | J41: 55809 | K41: 65631 | L41: 76484
B42: Borrowings -
B43: Long term Borrowings | C43: 23599 | D43: 30125 | E43: 33809 | F43: 43526 | G43: 52298 | H43: 52778 | I43: 48625 | J43: 55027 | K43: 69741 | L43: 83782
B44: Short term Borrowings | C44: 7077 | D44: 10122 | E44: 11326 | F44: 10541 | G44: 10218 | H44: 4647 | I44: 26042 | J44: 33740 | K44: 35484 | L44: 41466
B45: Lease Liabilities | C45: 0 | D45: 0 | E45: 0 | F45: 0 | G45: 0 | H45: 2666 | I45: 2938 | J45: 3480 | K45: 3422 | L45: 3776
B46: Preference Capital | C46: 0 | D46: 0 | E46: 0 | F46: 0 | G46: 0 | H46: 0 | I46: 0 | J46: 0 | K46: 2022 | L46: 4075
B47: Other Borrowings | C47: 10877 | D47: 8516 | E47: 10763 | F47: 16781 | G47: 19577 | H47: 20533 | I47: 0 | J47: 0 | K47: -2022 | L47: -4075
B48: Other Liabilities -
B49: Non controlling int | C49: 5920 | D49: 6357 | E49: 8250 | F49: 8361 | G49: 7692 | H49: 9070 | I49: 9703 | J49: 10716 | K49: 11319 | L49: 12059
B50: Trade Payables | C50: 13376 | D50: 14797 | E50: 18287 | F50: 20992 | G50: 14985 | H50: 15506 | I50: 19037 | J50: 23836 | K50: 25666 | L50: 30855
B51: Advance from Customers | C51: 801 | D51: 515 | E51: 844 | F51: 0 | G51: 0 | H51: 0 | I51: 0 | J51: 0 | K51: 0 | L51: 0
B52: Other liability items | C52: 11709 | D52: 13627 | E52: 16314 | F52: 21704 | G52: 20977 | H52: 18185 | I52: 18921 | J52: 21119 | K52: 22900 | L52: 27035
B53: Total Liabilities | C53: 99852 | D53: 113835 | E53: 136369 | F53: 161889 | G53: 165716 | H53: 164968 | I53: 172388 | J53: 204283 | K53: 234720 | L53: 276015
B54: Fixed Assets -
B55: Land | C55: 3575 | D55: 4027 | E55: 4285 | F55: 4295 | G55: 4511 | H55: 1712 | I55: 1931 | J55: 1977 | K55: 2098 | L55: 2115
B56: Building | C56: 7958 | D56: 8084 | E56: 8842 | F56: 9037 | G56: 11956 | H56: 8482 | I56: 9728 | J56: 10862 | K56: 11496 | L56: 13100
B57: Plant Machinery | C57: 27333 | D57: 28316 | E57: 32713 | F57: 35762 | G57: 38492 | H57: 22386 | I57: 26484 | J57: 24928 | K57: 27230 | L57: 32547
B58: Equipments | C58: 317 | D58: 351 | E58: 372 | F58: 384 | G58: 417 | H58: 418 | I58: 445 | J58: 452 | K58: 481 | L58: 493
...

Sheet Raw Data
A1: COMPANY NAME | B1: MAHINDRA & MAHINDRA LTD | E1: =IF(B2<>B3, "A NEW VERSION OF THE WORKSHEET IS AVAILABLE", "")
A2: LATEST VERSION | B2: 2.1 | E2: PLEASE DO NOT MAKE ANY CHANGES TO THIS SHEET
A3: CURRENT VERSION | B3: 2.1
A5: META
A6: Number of shares | B6: =IF(B9>0, B9/B8, 0) -> 124.35966
A7: Face Value | B7: 5
A8: Current Price | B8: 3717.1
A9: Market Capitalization | B9: 462257.29
A15: PROFIT & LOSS
A16: Report Date | B16: 42460 | C16: 42825 | D16: 43190 | E16: 43555 | F16: 43921 | G16: 44286 | H16: 44651 | I16: 45016 | J16: 45382 | K16: 45747
A17: Sales | B17: 75841.42 | C17: 83773.05 | D17: 92093.95 | E17: 104720.68 | F17: 75381.93 | G17: 74277.78 | H17: 90170.57 | I17: 121268.55 | J17: 139078.27 | K17: 159210.82
A18: Raw Material Cost | B18: 45584.35 | C18: 50655.2 | D18: 53457.29 | E18: 61881.19 | F18: 37595.3 | G18: 38271.2 | H18: 52664.85 | I18: 76019.87 | J18: 85070.07 | K18: 95754.9
A19: Change in Inventory | B19: 458.51 | C19: 13.83 | D19: -83.33 | E19: 1730.48 | F19: -826.62 | G19: -135.59 | H19: 861.66 | I19: 2032.31 | J19: 1455.32 | K19: 12.18
A20: Power and Fuel | B20: 639.97 | C20: 657.06 | D20: 733.9 | E20: 817.11 | F20: 530.92 | G20: 429.56 | H20: 541.27 | I20: 830.48 | J20: 752.73 | K20: 832.35
A21: Other Mfr. Exp | B21: 2618.7 | C21: 3255.3 | D21: 3590.26 | E21: 4253 | F21: 3277.79 | G21: 2523.4 | H21: 3124.27 | I21: 3838.42 | J21: 3791.75 | K21: 4162.28
A22: Employee Cost | B22: 7689.4 | C22: 8910.63 | D22: 10004.62 | E22: 11242.08 | F22: 8214.82 | G22: 7813.26 | H22: 8386.74 | I22: 9677.95 | J22: 10624.33 | K22: 11126.17
A23: Selling and admin | B23: 5758.86 | C23: 6253.64 | D23: 7591.15 | E23: 9658.98 | F23: 6316.52 | G23: 4628.75 | H23: 5977.67 | I23: 7681.87 | J23: 9832.2 | K23: 10811.4
A24: Other Expenses | B24: 3926.21 | C24: 3320.22 | D24: 3407.3 | E24: 3392.29 | F24: 8462.21 | G24: 8989 | H24: 5654.58 | I24: 4966.98 | J24: 5570.58 | K24: 6017.71
A25: Other Income | B25: 1398.83 | C25: 2076.61 | D25: 4366.41 | E25: 2676.45 | F25: 884.69 | G25: 1151.51 | H25: 3204.47 | I25: 3961.45 | J25: 3297.85 | K25: 3718.47
A26: Depreciation | B26: 2441.65 | C26: 2812.72 | D26: 3279.9 | E26: 3990.77 | F26: 3366.68 | G26: 3378.11 | H26: 3507.5 | I26: 4356.81 | J26: 4723.78 | K26: 6073.65
A27: Interest | B27: 3367.59 | C27: 3648.46 | D27: 3987.09 | E27: 5021.35 | F27: 6021.15 | G27: 6102.22 | H27: 5018.05 | I27: 5829.7 | J27: 7488.21 | K27: 9083.39
... A31: Dividend Amount | B31: 648.96 | C31: 807.43 | D31: 814.7 | E31: 924.73 | F31: 260.51 | G31: 971.51 | H31: 1284.5 | I31: 1809.66 | J31: 2352.14 | K31: 2824.24
B34: =B28-B29 -> 3554.5 | C34: =C28-C29 -> 4050.53 | D34: =D28-D29 -> 7957.79 | E34: =E28-E29 -> 6016.85 | F34: =F28-F29 -> -321 | G34: =G28-G29 -> 1512.39 | H34: =H28-H29 -> 7253.01 | I34: =I28-I29 -> 11374.48 | ... K34: =K28-K29 -> 14073.17
A40: Quarters
A41: Report Date | B41: 45107 | C41: 45199 | D41: 45291 | E41: 45382 | F41: 45473 | G41: 45565 | H41: 45657 | I41: 45747 | J41: 45838 | K41: 45930
A42: Sales | B42: 33891.63 | C42: 34435.52 | D42: 35299.39 | E42: 35451.73 | F42: 37217.72 | G42: 37923.74 | H42: 41470.05 | I42: 42599.31 | J42: 45529.19 | K42: 46105.67
A43: Expenses | B43: 27642.4 | C43: 28705.94 | D43: 29075.41 | E43: 28847.82 | F43: 29974.6 | G43: 30790.34 | H43: 33239.32 | I43: 34688.37 | J43: 37301.39 | K43: 37176.58
A44: Other Income | B44: 1065 | C44: 811.95 | D44: 755.69 | E44: 750.44 | F44: 733.21 | G44: 1125.57 | H44: 718.59 | I44: 1141.1 | J44: 1395.06 | K44: 1144.76
A45: Depreciation | B45: 1127.5 | C45: 1138.64 | D45: 1122.59 | E45: 1335.05 | F45: 1247.77 | G45: 1301.99 | H45: 1495.17 | I45: 2028.72 | J45: 1547.56 | K45: 1668.89
A46: Interest | B46: 1718.84 | C46: 1835.19 | D46: 1944.88 | E46: 1989.3 | F46: 2107.69 | G46: 2217.02 | H46: 2362.16 | I46: 2396.52 | J46: 2431.19 | K46: 2347.03
A47: Profit before tax | B47: 4467.89 | C47: 3567.7 | D47: 3912.2 | E47: 4030 | F47: 4620.87 | G47: 4739.96 | H47: 5091.99 | I47: 4626.8 | J47: 5644.11 | K47: 6057.93
A48: Tax | B48: 784.02 | C48: 1083.73 | D48: 935.16 | E48: 905.06 | F48: 1075.09 | G48: 1378.9 | H48: 1467.51 | I48: 1084.95 | J48: 1267.53 | K48: 2094.18
A49: Net profit | B49: 3508.41 | C49: 2347.75 | D49: 2658.4 | E49: 2754.08 | F49: 3282.63 | G49: 3170.72 | H49: 3180.58 | I49: 3295.17 | J49: 4083.32 | K49: 3673.32
A50: Operating Profit | B50: 6249.23 | C50: 5729.58 | D50: 6223.98 | E50: 6603.91 | F50: 7243.12 | G50: 7133.4 | H50: 8230.73 | I50: 7910.94 | J50: 8227.8 | K50: 8929.09
A55: BALANCE SHEET
A56: Report Date | B56: 42460 | C56: 42825 | D56: 43190 | E56: 43555 | F56: 43921 | G56: 44286 | H56: 44651 | I56: 45016 | J56: 45382 | K56: 45747
A57: Equity Share Capital | B57: 270.4 | C57: 310.55 | D57: 543.13 | E57: 543.96 | F57: 554.28 | G57: 555.15 | H57: 556.06 | I57: 556.82 | J57: 557.38 | K57: 558.15
A58: Reserves | B58: 26222.25 | C58: 29467.1 | D58: 36232.06 | E58: 39439.45 | F58: 39415.03 | G58: 41026.77 | H58: 46566.58 | I58: 55808.97 | J58: 65633.17 | K58: 76480.71
A59: Borrowings | B59: 41552.93 | C59: 48761.91 | D59: 55897.92 | E59: 70848.3 | F59: 82092.28 | G59: 80624.83 | H59: 77605.21 | I59: 92246.85 | J59: 108647.25 | K59: 129024.58
A60: Other Liabilities | B60: 31806.24 | C60: 35295.92 | D60: 43696.2 | E60: 51056.95 | F60: 43654.54 | G60: 42761.58 | H60: 47660.64 | I60: 55670.49 | J60: 59883.94 | K60: 69949.72
...
